<?xml version='1.0'?>
<robot name="dummy" xmlns:xacro="http://www.ros.org/wiki/xacro">
  <!-- File containing the plugins -->
  <xacro:include filename="$(find robot)/urdf/dummy.gazebo" />
  
  <!-- 
  ******************************************************************************
  All robot links 
  ******************************************************************************
  -->
  
  <!-- Link 0: Robot footprint -->
  <link name="robot_footprint">
    <!-- Empty -->
  </link>

  <!-- Link 1: Robot chassis -->
  <link name='chassis'>
    <pose>0 0 0.5 0 0 0</pose>
    <inertial>
      <mass value="15.0"/>
      <origin xyz="0 0 0" rpy=" 0 0 0"/>
      <inertia
        ixx="0.1" ixy="0" ixz="0"
        iyy="0.1" iyz="0"
        izz="0.1"
      />
    </inertial>

    <visual name='chassis_visual'>
      <origin xyz="0 0 0" rpy=" 0 0 0"/>
      <geometry>
        <mesh 
          scale="0.9 0.6 0.6"
          filename="package://database/objects/models/robot/chassis.dae"
        />
      </geometry>
    </visual>
    <collision name='chassis_collision'>
      <origin xyz="0 0 0" rpy=" 0 0 0"/> 
      <geometry>
        <box size="0.4 0.2 0.15"/>
      </geometry>
    </collision>

    <visual name='back_caster_visual'>
      <origin xyz="-0.12 0 -0.05" rpy=" 0 0 0"/>
      <geometry>
        <sphere radius="0.05"/>
      </geometry>
    </visual>
    <collision name='back_caster_collision'>
      <origin xyz="-0.12 0 -0.05" rpy=" 0 0 0"/>
      <geometry>
        <sphere radius="0.0499"/>
      </geometry>
    </collision>
    
    <visual name='front_caster_visual'>
      <origin xyz="0.14 0 -0.05" rpy=" 0 0 0"/>
      <geometry>
        <sphere radius="0.05"/>
      </geometry>
    </visual>
    <collision name='front_caster_collision'>
      <origin xyz="0.14 0 -0.05" rpy=" 0 0 0"/>
      <geometry>
        <sphere radius="0.0499"/>
      </geometry>
    </collision>
  </link>

  <!-- Link 2: Left wheel -->
  <link name='left_wheel'>
    <inertial>
      <mass value="5.0"/>
      <origin xyz="0 0 0" rpy="0 1.5707 1.5707"/>
      <inertia
        ixx="0.1" ixy="0" ixz="0"
        iyy="0.1" iyz="0"
        izz="0.1"
      />
    </inertial>
    <visual name='left_wheel_visual'>
      <origin xyz="0 0 0" rpy="0 0 0"/>
      <geometry>
        <mesh 
          scale="0.9 0.9 0.9"
          filename="package://database/objects/models/robot/wheel.dae"
        />
      </geometry>
    </visual>
    <collision name='left_wheel_collision'>
      <origin xyz="0 0 0" rpy="0 1.5707 1.5707"/> 
      <geometry>
        <cylinder length="0.07" radius="0.1"/>
      </geometry>
    </collision>
  </link>

  <!-- Link 3: Right wheel -->
  <link name='right_wheel'>
    <inertial>
      <mass value="5.0"/>
      <origin xyz="0 0 0" rpy="0 1.5707 1.5707"/>
      <inertia
        ixx="0.1" ixy="0" ixz="0"
        iyy="0.1" iyz="0"
        izz="0.1"
      />
    </inertial>
    <visual name='right_wheel_visual'>
      <origin xyz="0 0 0" rpy="0 0 0"/>
      <geometry>
        <mesh 
          scale="0.9 0.9 0.9"
          filename="package://database/objects/models/robot/wheel.dae"
        />
      </geometry>
    </visual>
    <collision name='right_wheel_collision'>
      <origin xyz="0 0 0" rpy="0 1.5707 1.5707"/> 
      <geometry>
        <cylinder length="0.07" radius="0.1"/>
      </geometry>
    </collision>
  </link>

  <!-- Link 4: Camera RGB -->
  <link name = "camera">
    <inertial>
      <mass value="0.1"/>
      <origin xyz="0 0 0" rpy="0 0 0"/>
      <inertia
        ixx="1e-6" ixy="0" ixz="0" 
        iyy="1e-6" iyz="0" 
        izz="1e-6"
      />
      <box_inertia m="0.1" x="0.05" y="0.05" z="0.05"/>
    </inertial>
    <visual name='camera_visual'>
      <origin xyz="0 0 0" rpy="0 0 0"/>
      <geometry>
       <mesh filename="package://database/objects/models/camera/kinect.dae"/>
      </geometry>
    </visual>
    <collision name='camera_collision'>
      <origin xyz="0 0 0" rpy="0 0 0"/> 
      <geometry>
        <box size = "0.06 0.28 0.05"/>
      </geometry>
    </collision>
  </link>

  <!-- Link 4: Camera RGBD -->
  <link name="camera_optical">
    <!-- Empty -->
  </link>

  <!-- Link 5: Laser scanner -->
  <link name = "hokuyo">
    <origin xyz="0 0 5" rpy="0 0 0"/>
    <inertial>
      <mass value = "1e-5"/>
      <origin xyz="0 0 0" rpy="0 0 0"/>
      <inertia
          ixx="1e-6" ixy="0" ixz="0" 
          iyy="1e-6" iyz="0" 
          izz="1e-6"
      />
    </inertial>
    <visual name='hokuyo_visual'>
      <origin xyz="0 0 0" rpy="0 0 0"/>
      <geometry>
       <mesh filename="package://database/objects/models/lidar/hokuyo.dae"/>
     </geometry>
    </visual>
    <collision name='hokuyo_collision'>
      <origin xyz="0 0 0" rpy="0 0 0"/> 
      <geometry>
        <box size="0.05 0.05 0.07"/>
      </geometry>
    </collision>
  </link>

  <!-- 
  ******************************************************************************
  All robot joints 
  ******************************************************************************
  -->

  <!-- Footprint to chassis -->
  <joint name="robot_footprint_joint" type="fixed">
    <origin xyz="0 0 0" rpy="0 0 0" />
    <parent link="robot_footprint"/>
    <child link="chassis" />
  </joint>

  <!-- Chassis to wheels-->
  <joint type="continuous" name="left_wheel_hinge">
    <origin xyz="0 0.15 0" rpy="0 0 0"/>
    <parent link="chassis"/>
    <child link="left_wheel"/>
    <axis xyz="0 1 0" rpy="0 0 0"/>
    <limit effort="10000" velocity="1000"/>
    <dynamics damping="1.0" friction="1.0"/>
  </joint>
  <joint type="continuous" name="right_wheel_hinge">
    <origin xyz="0 -0.15 0" rpy="0 0 0"/>
    <parent link="chassis"/>
    <child link="right_wheel"/>
    <axis xyz="0 1 0" rpy="0 0 0"/>
    <limit effort="10000" velocity="1000"/>
    <dynamics damping="1.0" friction="1.0"/>
  </joint>

  <!-- Chassis to sensors -->
  <joint type="fixed" name="camera_joint">
    <origin xyz="0.16 0 0.07" rpy="0 0 0"/>
    <parent link="chassis"/>
    <child link="camera"/>
  </joint>
  <joint name="camera_optical_joint" type="fixed">
    <origin xyz="0 0 0" rpy="-1.5707 0 -1.5707"/>
    <parent link="camera"/>
    <child link="camera_optical"/>
  </joint>
  <joint type="fixed" name="hokuyo_joint">
    <origin xyz="0.23 0 -0.05" rpy="0 0 0"/>
    <parent link="chassis"/>
    <child link="hokuyo"/>
  </joint>
</robot>